[2025-02-09 02:27:47] [INFO    ] discord.client: logging in using static token
[2025-02-09 02:27:48] [INFO    ] discord.gateway: Shard ID None has connected to Gateway (Session ID: 9497bf5fb2bc982b0d2b9967c1a937cb).
[2025-02-09 02:28:29] [INFO    ] discord.voice_state: Connecting to voice...
[2025-02-09 02:28:29] [INFO    ] discord.voice_state: Starting voice handshake... (connection attempt 1)
[2025-02-09 02:28:29] [INFO    ] discord.voice_state: Voice handshake complete. Endpoint found: rotterdam5873.discord.media
[2025-02-09 02:28:29] [INFO    ] discord.voice_state: Voice connection complete.
[2025-02-09 02:28:33] [INFO    ] discord.voice_state: The voice handshake is being terminated for Channel ID 1335365058796191789 (Guild ID 1335365058796191785)
[2025-02-09 02:28:33] [INFO    ] discord.player: ffmpeg process 37376 has not terminated. Waiting to terminate...
[2025-02-09 02:28:33] [INFO    ] discord.player: ffmpeg process 37376 should have terminated with a return code of -9.
[2025-02-09 02:28:36] [ERROR   ] discord.client: Ignoring exception in on_message
Traceback (most recent call last):
  File "/home/tagordo/snap/code/179/.local/share/virtualenvs/music-quiz-bot-PZw_aL80/lib/python3.12/site-packages/discord/client.py", line 449, in _run_event
    await coro(*args, **kwargs)
  File "/home/tagordo/Documents/side-projects/music-quiz-bot/bot/cogs/musicQuiz.py", line 140, in on_message
    if self.game['artist_guessed'] and self.game['song_guessed']:
       ~~~~~~~~~^^^^^^^^^^^^^^^^^^
KeyError: 'artist_guessed'
[2025-02-09 06:15:12] [INFO    ] discord.gateway: Shard ID None has successfully RESUMED session 9497bf5fb2bc982b0d2b9967c1a937cb.
[2025-02-09 06:23:01] [ERROR   ] discord.client: Attempting a reconnect in 0.52s
Traceback (most recent call last):
  File "/home/tagordo/snap/code/179/.local/share/virtualenvs/music-quiz-bot-PZw_aL80/lib/python3.12/site-packages/discord/client.py", line 667, in connect
    await self.ws.poll_event()
  File "/home/tagordo/snap/code/179/.local/share/virtualenvs/music-quiz-bot-PZw_aL80/lib/python3.12/site-packages/discord/gateway.py", line 625, in poll_event
    await self.received_message(msg.data)
  File "/home/tagordo/snap/code/179/.local/share/virtualenvs/music-quiz-bot-PZw_aL80/lib/python3.12/site-packages/discord/gateway.py", line 533, in received_message
    await self.send_as_json(beat)
  File "/home/tagordo/snap/code/179/.local/share/virtualenvs/music-quiz-bot-PZw_aL80/lib/python3.12/site-packages/discord/gateway.py", line 661, in send_as_json
    await self.send(utils._to_json(data))
  File "/home/tagordo/snap/code/179/.local/share/virtualenvs/music-quiz-bot-PZw_aL80/lib/python3.12/site-packages/discord/gateway.py", line 657, in send
    await self.socket.send_str(data)
  File "/home/tagordo/snap/code/179/.local/share/virtualenvs/music-quiz-bot-PZw_aL80/lib/python3.12/site-packages/aiohttp/client_ws.py", line 243, in send_str
    await self._writer.send_frame(
  File "/home/tagordo/snap/code/179/.local/share/virtualenvs/music-quiz-bot-PZw_aL80/lib/python3.12/site-packages/aiohttp/_websocket/writer.py", line 125, in send_frame
    raise ClientConnectionResetError("Cannot write to closing transport")
aiohttp.client_exceptions.ClientConnectionResetError: Cannot write to closing transport
[2025-02-09 06:23:02] [INFO    ] discord.gateway: Shard ID None has successfully RESUMED session 9497bf5fb2bc982b0d2b9967c1a937cb.
[2025-02-09 06:24:35] [WARNING ] discord.gateway: Can't keep up, shard ID None websocket is 27.9s behind.
[2025-02-09 06:25:38] [INFO    ] discord.gateway: Shard ID None has successfully RESUMED session 9497bf5fb2bc982b0d2b9967c1a937cb.
[2025-02-09 08:37:58] [ERROR   ] discord.client: Attempting a reconnect in 1.14s
Traceback (most recent call last):
  File "/home/tagordo/snap/code/179/.local/share/virtualenvs/music-quiz-bot-PZw_aL80/lib/python3.12/site-packages/aiohttp/connector.py", line 1351, in _create_direct_connection
    hosts = await self._resolve_host(host, port, traces=traces)
            ^^^^^^^^^^^^^^^^^^^^^^^^^^^^^^^^^^^^^^^^^^^^^^^^^^^
  File "/home/tagordo/snap/code/179/.local/share/virtualenvs/music-quiz-bot-PZw_aL80/lib/python3.12/site-packages/aiohttp/connector.py", line 995, in _resolve_host
    return await asyncio.shield(resolved_host_task)
           ^^^^^^^^^^^^^^^^^^^^^^^^^^^^^^^^^^^^^^^^
  File "/home/tagordo/snap/code/179/.local/share/virtualenvs/music-quiz-bot-PZw_aL80/lib/python3.12/site-packages/aiohttp/connector.py", line 1026, in _resolve_host_with_throttle
    addrs = await self._resolver.resolve(host, port, family=self._family)
            ^^^^^^^^^^^^^^^^^^^^^^^^^^^^^^^^^^^^^^^^^^^^^^^^^^^^^^^^^^^^^
  File "/home/tagordo/snap/code/179/.local/share/virtualenvs/music-quiz-bot-PZw_aL80/lib/python3.12/site-packages/aiohttp/resolver.py", line 36, in resolve
    infos = await self._loop.getaddrinfo(
            ^^^^^^^^^^^^^^^^^^^^^^^^^^^^^
  File "/usr/lib/python3.12/asyncio/base_events.py", line 901, in getaddrinfo
    return await self.run_in_executor(
           ^^^^^^^^^^^^^^^^^^^^^^^^^^^
  File "/usr/lib/python3.12/concurrent/futures/thread.py", line 58, in run
    result = self.fn(*self.args, **self.kwargs)
             ^^^^^^^^^^^^^^^^^^^^^^^^^^^^^^^^^^
  File "/usr/lib/python3.12/socket.py", line 963, in getaddrinfo
    for res in _socket.getaddrinfo(host, port, family, type, proto, flags):
               ^^^^^^^^^^^^^^^^^^^^^^^^^^^^^^^^^^^^^^^^^^^^^^^^^^^^^^^^^^^
socket.gaierror: [Errno -3] Temporary failure in name resolution

The above exception was the direct cause of the following exception:

Traceback (most recent call last):
  File "/home/tagordo/snap/code/179/.local/share/virtualenvs/music-quiz-bot-PZw_aL80/lib/python3.12/site-packages/discord/client.py", line 664, in connect
    self.ws = await asyncio.wait_for(coro, timeout=60.0)
              ^^^^^^^^^^^^^^^^^^^^^^^^^^^^^^^^^^^^^^^^^^
  File "/usr/lib/python3.12/asyncio/tasks.py", line 520, in wait_for
    return await fut
           ^^^^^^^^^
  File "/home/tagordo/snap/code/179/.local/share/virtualenvs/music-quiz-bot-PZw_aL80/lib/python3.12/site-packages/discord/gateway.py", line 374, in from_client
    socket = await client.http.ws_connect(str(url))
             ^^^^^^^^^^^^^^^^^^^^^^^^^^^^^^^^^^^^^^
  File "/home/tagordo/snap/code/179/.local/share/virtualenvs/music-quiz-bot-PZw_aL80/lib/python3.12/site-packages/discord/http.py", line 550, in ws_connect
    return await self.__session.ws_connect(url, **kwargs)
           ^^^^^^^^^^^^^^^^^^^^^^^^^^^^^^^^^^^^^^^^^^^^^^
  File "/home/tagordo/snap/code/179/.local/share/virtualenvs/music-quiz-bot-PZw_aL80/lib/python3.12/site-packages/aiohttp/client.py", line 1004, in _ws_connect
    resp = await self.request(
           ^^^^^^^^^^^^^^^^^^^
  File "/home/tagordo/snap/code/179/.local/share/virtualenvs/music-quiz-bot-PZw_aL80/lib/python3.12/site-packages/aiohttp/client.py", line 703, in _request
    conn = await self._connector.connect(
           ^^^^^^^^^^^^^^^^^^^^^^^^^^^^^^
  File "/home/tagordo/snap/code/179/.local/share/virtualenvs/music-quiz-bot-PZw_aL80/lib/python3.12/site-packages/aiohttp/connector.py", line 548, in connect
    proto = await self._create_connection(req, traces, timeout)
            ^^^^^^^^^^^^^^^^^^^^^^^^^^^^^^^^^^^^^^^^^^^^^^^^^^^
  File "/home/tagordo/snap/code/179/.local/share/virtualenvs/music-quiz-bot-PZw_aL80/lib/python3.12/site-packages/aiohttp/connector.py", line 1056, in _create_connection
    _, proto = await self._create_direct_connection(req, traces, timeout)
               ^^^^^^^^^^^^^^^^^^^^^^^^^^^^^^^^^^^^^^^^^^^^^^^^^^^^^^^^^^
  File "/home/tagordo/snap/code/179/.local/share/virtualenvs/music-quiz-bot-PZw_aL80/lib/python3.12/site-packages/aiohttp/connector.py", line 1357, in _create_direct_connection
    raise ClientConnectorDNSError(req.connection_key, exc) from exc
aiohttp.client_exceptions.ClientConnectorDNSError: Cannot connect to host gateway-us-east1-d.discord.gg:443 ssl:default [Temporary failure in name resolution]
[2025-02-09 08:37:59] [ERROR   ] discord.client: Attempting a reconnect in 0.62s
Traceback (most recent call last):
  File "/home/tagordo/snap/code/179/.local/share/virtualenvs/music-quiz-bot-PZw_aL80/lib/python3.12/site-packages/aiohttp/connector.py", line 1351, in _create_direct_connection
    hosts = await self._resolve_host(host, port, traces=traces)
            ^^^^^^^^^^^^^^^^^^^^^^^^^^^^^^^^^^^^^^^^^^^^^^^^^^^
  File "/home/tagordo/snap/code/179/.local/share/virtualenvs/music-quiz-bot-PZw_aL80/lib/python3.12/site-packages/aiohttp/connector.py", line 995, in _resolve_host
    return await asyncio.shield(resolved_host_task)
           ^^^^^^^^^^^^^^^^^^^^^^^^^^^^^^^^^^^^^^^^
  File "/home/tagordo/snap/code/179/.local/share/virtualenvs/music-quiz-bot-PZw_aL80/lib/python3.12/site-packages/aiohttp/connector.py", line 1026, in _resolve_host_with_throttle
    addrs = await self._resolver.resolve(host, port, family=self._family)
            ^^^^^^^^^^^^^^^^^^^^^^^^^^^^^^^^^^^^^^^^^^^^^^^^^^^^^^^^^^^^^
  File "/home/tagordo/snap/code/179/.local/share/virtualenvs/music-quiz-bot-PZw_aL80/lib/python3.12/site-packages/aiohttp/resolver.py", line 36, in resolve
    infos = await self._loop.getaddrinfo(
            ^^^^^^^^^^^^^^^^^^^^^^^^^^^^^
  File "/usr/lib/python3.12/asyncio/base_events.py", line 901, in getaddrinfo
    return await self.run_in_executor(
           ^^^^^^^^^^^^^^^^^^^^^^^^^^^
  File "/usr/lib/python3.12/concurrent/futures/thread.py", line 58, in run
    result = self.fn(*self.args, **self.kwargs)
             ^^^^^^^^^^^^^^^^^^^^^^^^^^^^^^^^^^
  File "/usr/lib/python3.12/socket.py", line 963, in getaddrinfo
    for res in _socket.getaddrinfo(host, port, family, type, proto, flags):
               ^^^^^^^^^^^^^^^^^^^^^^^^^^^^^^^^^^^^^^^^^^^^^^^^^^^^^^^^^^^
socket.gaierror: [Errno -3] Temporary failure in name resolution

The above exception was the direct cause of the following exception:

Traceback (most recent call last):
  File "/home/tagordo/snap/code/179/.local/share/virtualenvs/music-quiz-bot-PZw_aL80/lib/python3.12/site-packages/discord/client.py", line 664, in connect
    self.ws = await asyncio.wait_for(coro, timeout=60.0)
              ^^^^^^^^^^^^^^^^^^^^^^^^^^^^^^^^^^^^^^^^^^
  File "/usr/lib/python3.12/asyncio/tasks.py", line 520, in wait_for
    return await fut
           ^^^^^^^^^
  File "/home/tagordo/snap/code/179/.local/share/virtualenvs/music-quiz-bot-PZw_aL80/lib/python3.12/site-packages/discord/gateway.py", line 374, in from_client
    socket = await client.http.ws_connect(str(url))
             ^^^^^^^^^^^^^^^^^^^^^^^^^^^^^^^^^^^^^^
  File "/home/tagordo/snap/code/179/.local/share/virtualenvs/music-quiz-bot-PZw_aL80/lib/python3.12/site-packages/discord/http.py", line 550, in ws_connect
    return await self.__session.ws_connect(url, **kwargs)
           ^^^^^^^^^^^^^^^^^^^^^^^^^^^^^^^^^^^^^^^^^^^^^^
  File "/home/tagordo/snap/code/179/.local/share/virtualenvs/music-quiz-bot-PZw_aL80/lib/python3.12/site-packages/aiohttp/client.py", line 1004, in _ws_connect
    resp = await self.request(
           ^^^^^^^^^^^^^^^^^^^
  File "/home/tagordo/snap/code/179/.local/share/virtualenvs/music-quiz-bot-PZw_aL80/lib/python3.12/site-packages/aiohttp/client.py", line 703, in _request
    conn = await self._connector.connect(
           ^^^^^^^^^^^^^^^^^^^^^^^^^^^^^^
  File "/home/tagordo/snap/code/179/.local/share/virtualenvs/music-quiz-bot-PZw_aL80/lib/python3.12/site-packages/aiohttp/connector.py", line 548, in connect
    proto = await self._create_connection(req, traces, timeout)
            ^^^^^^^^^^^^^^^^^^^^^^^^^^^^^^^^^^^^^^^^^^^^^^^^^^^
  File "/home/tagordo/snap/code/179/.local/share/virtualenvs/music-quiz-bot-PZw_aL80/lib/python3.12/site-packages/aiohttp/connector.py", line 1056, in _create_connection
    _, proto = await self._create_direct_connection(req, traces, timeout)
               ^^^^^^^^^^^^^^^^^^^^^^^^^^^^^^^^^^^^^^^^^^^^^^^^^^^^^^^^^^
  File "/home/tagordo/snap/code/179/.local/share/virtualenvs/music-quiz-bot-PZw_aL80/lib/python3.12/site-packages/aiohttp/connector.py", line 1357, in _create_direct_connection
    raise ClientConnectorDNSError(req.connection_key, exc) from exc
aiohttp.client_exceptions.ClientConnectorDNSError: Cannot connect to host gateway-us-east1-d.discord.gg:443 ssl:default [Temporary failure in name resolution]
[2025-02-09 08:37:59] [ERROR   ] discord.client: Attempting a reconnect in 1.85s
Traceback (most recent call last):
  File "/home/tagordo/snap/code/179/.local/share/virtualenvs/music-quiz-bot-PZw_aL80/lib/python3.12/site-packages/aiohttp/connector.py", line 1351, in _create_direct_connection
    hosts = await self._resolve_host(host, port, traces=traces)
            ^^^^^^^^^^^^^^^^^^^^^^^^^^^^^^^^^^^^^^^^^^^^^^^^^^^
  File "/home/tagordo/snap/code/179/.local/share/virtualenvs/music-quiz-bot-PZw_aL80/lib/python3.12/site-packages/aiohttp/connector.py", line 995, in _resolve_host
    return await asyncio.shield(resolved_host_task)
           ^^^^^^^^^^^^^^^^^^^^^^^^^^^^^^^^^^^^^^^^
  File "/home/tagordo/snap/code/179/.local/share/virtualenvs/music-quiz-bot-PZw_aL80/lib/python3.12/site-packages/aiohttp/connector.py", line 1026, in _resolve_host_with_throttle
    addrs = await self._resolver.resolve(host, port, family=self._family)
            ^^^^^^^^^^^^^^^^^^^^^^^^^^^^^^^^^^^^^^^^^^^^^^^^^^^^^^^^^^^^^
  File "/home/tagordo/snap/code/179/.local/share/virtualenvs/music-quiz-bot-PZw_aL80/lib/python3.12/site-packages/aiohttp/resolver.py", line 36, in resolve
    infos = await self._loop.getaddrinfo(
            ^^^^^^^^^^^^^^^^^^^^^^^^^^^^^
  File "/usr/lib/python3.12/asyncio/base_events.py", line 901, in getaddrinfo
    return await self.run_in_executor(
           ^^^^^^^^^^^^^^^^^^^^^^^^^^^
  File "/usr/lib/python3.12/concurrent/futures/thread.py", line 58, in run
    result = self.fn(*self.args, **self.kwargs)
             ^^^^^^^^^^^^^^^^^^^^^^^^^^^^^^^^^^
  File "/usr/lib/python3.12/socket.py", line 963, in getaddrinfo
    for res in _socket.getaddrinfo(host, port, family, type, proto, flags):
               ^^^^^^^^^^^^^^^^^^^^^^^^^^^^^^^^^^^^^^^^^^^^^^^^^^^^^^^^^^^
socket.gaierror: [Errno -3] Temporary failure in name resolution

The above exception was the direct cause of the following exception:

Traceback (most recent call last):
  File "/home/tagordo/snap/code/179/.local/share/virtualenvs/music-quiz-bot-PZw_aL80/lib/python3.12/site-packages/discord/client.py", line 664, in connect
    self.ws = await asyncio.wait_for(coro, timeout=60.0)
              ^^^^^^^^^^^^^^^^^^^^^^^^^^^^^^^^^^^^^^^^^^
  File "/usr/lib/python3.12/asyncio/tasks.py", line 520, in wait_for
    return await fut
           ^^^^^^^^^
  File "/home/tagordo/snap/code/179/.local/share/virtualenvs/music-quiz-bot-PZw_aL80/lib/python3.12/site-packages/discord/gateway.py", line 374, in from_client
    socket = await client.http.ws_connect(str(url))
             ^^^^^^^^^^^^^^^^^^^^^^^^^^^^^^^^^^^^^^
  File "/home/tagordo/snap/code/179/.local/share/virtualenvs/music-quiz-bot-PZw_aL80/lib/python3.12/site-packages/discord/http.py", line 550, in ws_connect
    return await self.__session.ws_connect(url, **kwargs)
           ^^^^^^^^^^^^^^^^^^^^^^^^^^^^^^^^^^^^^^^^^^^^^^
  File "/home/tagordo/snap/code/179/.local/share/virtualenvs/music-quiz-bot-PZw_aL80/lib/python3.12/site-packages/aiohttp/client.py", line 1004, in _ws_connect
    resp = await self.request(
           ^^^^^^^^^^^^^^^^^^^
  File "/home/tagordo/snap/code/179/.local/share/virtualenvs/music-quiz-bot-PZw_aL80/lib/python3.12/site-packages/aiohttp/client.py", line 703, in _request
    conn = await self._connector.connect(
           ^^^^^^^^^^^^^^^^^^^^^^^^^^^^^^
  File "/home/tagordo/snap/code/179/.local/share/virtualenvs/music-quiz-bot-PZw_aL80/lib/python3.12/site-packages/aiohttp/connector.py", line 548, in connect
    proto = await self._create_connection(req, traces, timeout)
            ^^^^^^^^^^^^^^^^^^^^^^^^^^^^^^^^^^^^^^^^^^^^^^^^^^^
  File "/home/tagordo/snap/code/179/.local/share/virtualenvs/music-quiz-bot-PZw_aL80/lib/python3.12/site-packages/aiohttp/connector.py", line 1056, in _create_connection
    _, proto = await self._create_direct_connection(req, traces, timeout)
               ^^^^^^^^^^^^^^^^^^^^^^^^^^^^^^^^^^^^^^^^^^^^^^^^^^^^^^^^^^
  File "/home/tagordo/snap/code/179/.local/share/virtualenvs/music-quiz-bot-PZw_aL80/lib/python3.12/site-packages/aiohttp/connector.py", line 1357, in _create_direct_connection
    raise ClientConnectorDNSError(req.connection_key, exc) from exc
aiohttp.client_exceptions.ClientConnectorDNSError: Cannot connect to host gateway-us-east1-d.discord.gg:443 ssl:default [Temporary failure in name resolution]
[2025-02-09 08:38:01] [ERROR   ] discord.client: Attempting a reconnect in 5.10s
Traceback (most recent call last):
  File "/home/tagordo/snap/code/179/.local/share/virtualenvs/music-quiz-bot-PZw_aL80/lib/python3.12/site-packages/aiohttp/connector.py", line 1351, in _create_direct_connection
    hosts = await self._resolve_host(host, port, traces=traces)
            ^^^^^^^^^^^^^^^^^^^^^^^^^^^^^^^^^^^^^^^^^^^^^^^^^^^
  File "/home/tagordo/snap/code/179/.local/share/virtualenvs/music-quiz-bot-PZw_aL80/lib/python3.12/site-packages/aiohttp/connector.py", line 995, in _resolve_host
    return await asyncio.shield(resolved_host_task)
           ^^^^^^^^^^^^^^^^^^^^^^^^^^^^^^^^^^^^^^^^
  File "/home/tagordo/snap/code/179/.local/share/virtualenvs/music-quiz-bot-PZw_aL80/lib/python3.12/site-packages/aiohttp/connector.py", line 1026, in _resolve_host_with_throttle
    addrs = await self._resolver.resolve(host, port, family=self._family)
            ^^^^^^^^^^^^^^^^^^^^^^^^^^^^^^^^^^^^^^^^^^^^^^^^^^^^^^^^^^^^^
  File "/home/tagordo/snap/code/179/.local/share/virtualenvs/music-quiz-bot-PZw_aL80/lib/python3.12/site-packages/aiohttp/resolver.py", line 36, in resolve
    infos = await self._loop.getaddrinfo(
            ^^^^^^^^^^^^^^^^^^^^^^^^^^^^^
  File "/usr/lib/python3.12/asyncio/base_events.py", line 901, in getaddrinfo
    return await self.run_in_executor(
           ^^^^^^^^^^^^^^^^^^^^^^^^^^^
  File "/usr/lib/python3.12/concurrent/futures/thread.py", line 58, in run
    result = self.fn(*self.args, **self.kwargs)
             ^^^^^^^^^^^^^^^^^^^^^^^^^^^^^^^^^^
  File "/usr/lib/python3.12/socket.py", line 963, in getaddrinfo
    for res in _socket.getaddrinfo(host, port, family, type, proto, flags):
               ^^^^^^^^^^^^^^^^^^^^^^^^^^^^^^^^^^^^^^^^^^^^^^^^^^^^^^^^^^^
socket.gaierror: [Errno -3] Temporary failure in name resolution

The above exception was the direct cause of the following exception:

Traceback (most recent call last):
  File "/home/tagordo/snap/code/179/.local/share/virtualenvs/music-quiz-bot-PZw_aL80/lib/python3.12/site-packages/discord/client.py", line 664, in connect
    self.ws = await asyncio.wait_for(coro, timeout=60.0)
              ^^^^^^^^^^^^^^^^^^^^^^^^^^^^^^^^^^^^^^^^^^
  File "/usr/lib/python3.12/asyncio/tasks.py", line 520, in wait_for
    return await fut
           ^^^^^^^^^
  File "/home/tagordo/snap/code/179/.local/share/virtualenvs/music-quiz-bot-PZw_aL80/lib/python3.12/site-packages/discord/gateway.py", line 374, in from_client
    socket = await client.http.ws_connect(str(url))
             ^^^^^^^^^^^^^^^^^^^^^^^^^^^^^^^^^^^^^^
  File "/home/tagordo/snap/code/179/.local/share/virtualenvs/music-quiz-bot-PZw_aL80/lib/python3.12/site-packages/discord/http.py", line 550, in ws_connect
    return await self.__session.ws_connect(url, **kwargs)
           ^^^^^^^^^^^^^^^^^^^^^^^^^^^^^^^^^^^^^^^^^^^^^^
  File "/home/tagordo/snap/code/179/.local/share/virtualenvs/music-quiz-bot-PZw_aL80/lib/python3.12/site-packages/aiohttp/client.py", line 1004, in _ws_connect
    resp = await self.request(
           ^^^^^^^^^^^^^^^^^^^
  File "/home/tagordo/snap/code/179/.local/share/virtualenvs/music-quiz-bot-PZw_aL80/lib/python3.12/site-packages/aiohttp/client.py", line 703, in _request
    conn = await self._connector.connect(
           ^^^^^^^^^^^^^^^^^^^^^^^^^^^^^^
  File "/home/tagordo/snap/code/179/.local/share/virtualenvs/music-quiz-bot-PZw_aL80/lib/python3.12/site-packages/aiohttp/connector.py", line 548, in connect
    proto = await self._create_connection(req, traces, timeout)
            ^^^^^^^^^^^^^^^^^^^^^^^^^^^^^^^^^^^^^^^^^^^^^^^^^^^
  File "/home/tagordo/snap/code/179/.local/share/virtualenvs/music-quiz-bot-PZw_aL80/lib/python3.12/site-packages/aiohttp/connector.py", line 1056, in _create_connection
    _, proto = await self._create_direct_connection(req, traces, timeout)
               ^^^^^^^^^^^^^^^^^^^^^^^^^^^^^^^^^^^^^^^^^^^^^^^^^^^^^^^^^^
  File "/home/tagordo/snap/code/179/.local/share/virtualenvs/music-quiz-bot-PZw_aL80/lib/python3.12/site-packages/aiohttp/connector.py", line 1357, in _create_direct_connection
    raise ClientConnectorDNSError(req.connection_key, exc) from exc
aiohttp.client_exceptions.ClientConnectorDNSError: Cannot connect to host gateway-us-east1-d.discord.gg:443 ssl:default [Temporary failure in name resolution]
[2025-02-09 08:50:20] [ERROR   ] discord.client: Attempting a reconnect in 23.57s
Traceback (most recent call last):
  File "/home/tagordo/snap/code/179/.local/share/virtualenvs/music-quiz-bot-PZw_aL80/lib/python3.12/site-packages/aiohttp/connector.py", line 1351, in _create_direct_connection
    hosts = await self._resolve_host(host, port, traces=traces)
            ^^^^^^^^^^^^^^^^^^^^^^^^^^^^^^^^^^^^^^^^^^^^^^^^^^^
  File "/home/tagordo/snap/code/179/.local/share/virtualenvs/music-quiz-bot-PZw_aL80/lib/python3.12/site-packages/aiohttp/connector.py", line 995, in _resolve_host
    return await asyncio.shield(resolved_host_task)
           ^^^^^^^^^^^^^^^^^^^^^^^^^^^^^^^^^^^^^^^^
  File "/home/tagordo/snap/code/179/.local/share/virtualenvs/music-quiz-bot-PZw_aL80/lib/python3.12/site-packages/aiohttp/connector.py", line 1026, in _resolve_host_with_throttle
    addrs = await self._resolver.resolve(host, port, family=self._family)
            ^^^^^^^^^^^^^^^^^^^^^^^^^^^^^^^^^^^^^^^^^^^^^^^^^^^^^^^^^^^^^
  File "/home/tagordo/snap/code/179/.local/share/virtualenvs/music-quiz-bot-PZw_aL80/lib/python3.12/site-packages/aiohttp/resolver.py", line 36, in resolve
    infos = await self._loop.getaddrinfo(
            ^^^^^^^^^^^^^^^^^^^^^^^^^^^^^
  File "/usr/lib/python3.12/asyncio/base_events.py", line 901, in getaddrinfo
    return await self.run_in_executor(
           ^^^^^^^^^^^^^^^^^^^^^^^^^^^
  File "/usr/lib/python3.12/concurrent/futures/thread.py", line 58, in run
    result = self.fn(*self.args, **self.kwargs)
             ^^^^^^^^^^^^^^^^^^^^^^^^^^^^^^^^^^
  File "/usr/lib/python3.12/socket.py", line 963, in getaddrinfo
    for res in _socket.getaddrinfo(host, port, family, type, proto, flags):
               ^^^^^^^^^^^^^^^^^^^^^^^^^^^^^^^^^^^^^^^^^^^^^^^^^^^^^^^^^^^
socket.gaierror: [Errno -3] Temporary failure in name resolution

The above exception was the direct cause of the following exception:

Traceback (most recent call last):
  File "/home/tagordo/snap/code/179/.local/share/virtualenvs/music-quiz-bot-PZw_aL80/lib/python3.12/site-packages/discord/client.py", line 664, in connect
    self.ws = await asyncio.wait_for(coro, timeout=60.0)
              ^^^^^^^^^^^^^^^^^^^^^^^^^^^^^^^^^^^^^^^^^^
  File "/usr/lib/python3.12/asyncio/tasks.py", line 520, in wait_for
    return await fut
           ^^^^^^^^^
  File "/home/tagordo/snap/code/179/.local/share/virtualenvs/music-quiz-bot-PZw_aL80/lib/python3.12/site-packages/discord/gateway.py", line 374, in from_client
    socket = await client.http.ws_connect(str(url))
             ^^^^^^^^^^^^^^^^^^^^^^^^^^^^^^^^^^^^^^
  File "/home/tagordo/snap/code/179/.local/share/virtualenvs/music-quiz-bot-PZw_aL80/lib/python3.12/site-packages/discord/http.py", line 550, in ws_connect
    return await self.__session.ws_connect(url, **kwargs)
           ^^^^^^^^^^^^^^^^^^^^^^^^^^^^^^^^^^^^^^^^^^^^^^
  File "/home/tagordo/snap/code/179/.local/share/virtualenvs/music-quiz-bot-PZw_aL80/lib/python3.12/site-packages/aiohttp/client.py", line 1004, in _ws_connect
    resp = await self.request(
           ^^^^^^^^^^^^^^^^^^^
  File "/home/tagordo/snap/code/179/.local/share/virtualenvs/music-quiz-bot-PZw_aL80/lib/python3.12/site-packages/aiohttp/client.py", line 703, in _request
    conn = await self._connector.connect(
           ^^^^^^^^^^^^^^^^^^^^^^^^^^^^^^
  File "/home/tagordo/snap/code/179/.local/share/virtualenvs/music-quiz-bot-PZw_aL80/lib/python3.12/site-packages/aiohttp/connector.py", line 548, in connect
    proto = await self._create_connection(req, traces, timeout)
            ^^^^^^^^^^^^^^^^^^^^^^^^^^^^^^^^^^^^^^^^^^^^^^^^^^^
  File "/home/tagordo/snap/code/179/.local/share/virtualenvs/music-quiz-bot-PZw_aL80/lib/python3.12/site-packages/aiohttp/connector.py", line 1056, in _create_connection
    _, proto = await self._create_direct_connection(req, traces, timeout)
               ^^^^^^^^^^^^^^^^^^^^^^^^^^^^^^^^^^^^^^^^^^^^^^^^^^^^^^^^^^
  File "/home/tagordo/snap/code/179/.local/share/virtualenvs/music-quiz-bot-PZw_aL80/lib/python3.12/site-packages/aiohttp/connector.py", line 1357, in _create_direct_connection
    raise ClientConnectorDNSError(req.connection_key, exc) from exc
aiohttp.client_exceptions.ClientConnectorDNSError: Cannot connect to host gateway-us-east1-d.discord.gg:443 ssl:default [Temporary failure in name resolution]
[2025-02-09 08:50:44] [INFO    ] discord.gateway: Shard ID None session has been invalidated.
[2025-02-09 09:02:19] [ERROR   ] discord.client: Attempting a reconnect in 17.04s
Traceback (most recent call last):
  File "/usr/lib/python3.12/asyncio/tasks.py", line 520, in wait_for
    return await fut
           ^^^^^^^^^
  File "/home/tagordo/snap/code/179/.local/share/virtualenvs/music-quiz-bot-PZw_aL80/lib/python3.12/site-packages/discord/gateway.py", line 374, in from_client
    socket = await client.http.ws_connect(str(url))
             ^^^^^^^^^^^^^^^^^^^^^^^^^^^^^^^^^^^^^^
  File "/home/tagordo/snap/code/179/.local/share/virtualenvs/music-quiz-bot-PZw_aL80/lib/python3.12/site-packages/discord/http.py", line 550, in ws_connect
    return await self.__session.ws_connect(url, **kwargs)
           ^^^^^^^^^^^^^^^^^^^^^^^^^^^^^^^^^^^^^^^^^^^^^^
  File "/home/tagordo/snap/code/179/.local/share/virtualenvs/music-quiz-bot-PZw_aL80/lib/python3.12/site-packages/aiohttp/client.py", line 1004, in _ws_connect
    resp = await self.request(
           ^^^^^^^^^^^^^^^^^^^
  File "/home/tagordo/snap/code/179/.local/share/virtualenvs/music-quiz-bot-PZw_aL80/lib/python3.12/site-packages/aiohttp/client.py", line 730, in _request
    await resp.start(conn)
  File "/home/tagordo/snap/code/179/.local/share/virtualenvs/music-quiz-bot-PZw_aL80/lib/python3.12/site-packages/aiohttp/client_reqrep.py", line 1059, in start
    message, payload = await protocol.read()  # type: ignore[union-attr]
                       ^^^^^^^^^^^^^^^^^^^^^
  File "/home/tagordo/snap/code/179/.local/share/virtualenvs/music-quiz-bot-PZw_aL80/lib/python3.12/site-packages/aiohttp/streams.py", line 671, in read
    await self._waiter
asyncio.exceptions.CancelledError

The above exception was the direct cause of the following exception:

Traceback (most recent call last):
  File "/home/tagordo/snap/code/179/.local/share/virtualenvs/music-quiz-bot-PZw_aL80/lib/python3.12/site-packages/discord/client.py", line 664, in connect
    self.ws = await asyncio.wait_for(coro, timeout=60.0)
              ^^^^^^^^^^^^^^^^^^^^^^^^^^^^^^^^^^^^^^^^^^
  File "/usr/lib/python3.12/asyncio/tasks.py", line 519, in wait_for
    async with timeouts.timeout(timeout):
  File "/usr/lib/python3.12/asyncio/timeouts.py", line 115, in __aexit__
    raise TimeoutError from exc_val
TimeoutError
[2025-02-09 09:02:36] [ERROR   ] discord.client: Attempting a reconnect in 44.53s
Traceback (most recent call last):
  File "/home/tagordo/snap/code/179/.local/share/virtualenvs/music-quiz-bot-PZw_aL80/lib/python3.12/site-packages/aiohttp/connector.py", line 1351, in _create_direct_connection
    hosts = await self._resolve_host(host, port, traces=traces)
            ^^^^^^^^^^^^^^^^^^^^^^^^^^^^^^^^^^^^^^^^^^^^^^^^^^^
  File "/home/tagordo/snap/code/179/.local/share/virtualenvs/music-quiz-bot-PZw_aL80/lib/python3.12/site-packages/aiohttp/connector.py", line 995, in _resolve_host
    return await asyncio.shield(resolved_host_task)
           ^^^^^^^^^^^^^^^^^^^^^^^^^^^^^^^^^^^^^^^^
  File "/home/tagordo/snap/code/179/.local/share/virtualenvs/music-quiz-bot-PZw_aL80/lib/python3.12/site-packages/aiohttp/connector.py", line 1026, in _resolve_host_with_throttle
    addrs = await self._resolver.resolve(host, port, family=self._family)
            ^^^^^^^^^^^^^^^^^^^^^^^^^^^^^^^^^^^^^^^^^^^^^^^^^^^^^^^^^^^^^
  File "/home/tagordo/snap/code/179/.local/share/virtualenvs/music-quiz-bot-PZw_aL80/lib/python3.12/site-packages/aiohttp/resolver.py", line 36, in resolve
    infos = await self._loop.getaddrinfo(
            ^^^^^^^^^^^^^^^^^^^^^^^^^^^^^
  File "/usr/lib/python3.12/asyncio/base_events.py", line 901, in getaddrinfo
    return await self.run_in_executor(
           ^^^^^^^^^^^^^^^^^^^^^^^^^^^
  File "/usr/lib/python3.12/concurrent/futures/thread.py", line 58, in run
    result = self.fn(*self.args, **self.kwargs)
             ^^^^^^^^^^^^^^^^^^^^^^^^^^^^^^^^^^
  File "/usr/lib/python3.12/socket.py", line 963, in getaddrinfo
    for res in _socket.getaddrinfo(host, port, family, type, proto, flags):
               ^^^^^^^^^^^^^^^^^^^^^^^^^^^^^^^^^^^^^^^^^^^^^^^^^^^^^^^^^^^
socket.gaierror: [Errno -3] Temporary failure in name resolution

The above exception was the direct cause of the following exception:

Traceback (most recent call last):
  File "/home/tagordo/snap/code/179/.local/share/virtualenvs/music-quiz-bot-PZw_aL80/lib/python3.12/site-packages/discord/client.py", line 664, in connect
    self.ws = await asyncio.wait_for(coro, timeout=60.0)
              ^^^^^^^^^^^^^^^^^^^^^^^^^^^^^^^^^^^^^^^^^^
  File "/usr/lib/python3.12/asyncio/tasks.py", line 520, in wait_for
    return await fut
           ^^^^^^^^^
  File "/home/tagordo/snap/code/179/.local/share/virtualenvs/music-quiz-bot-PZw_aL80/lib/python3.12/site-packages/discord/gateway.py", line 374, in from_client
    socket = await client.http.ws_connect(str(url))
             ^^^^^^^^^^^^^^^^^^^^^^^^^^^^^^^^^^^^^^
  File "/home/tagordo/snap/code/179/.local/share/virtualenvs/music-quiz-bot-PZw_aL80/lib/python3.12/site-packages/discord/http.py", line 550, in ws_connect
    return await self.__session.ws_connect(url, **kwargs)
           ^^^^^^^^^^^^^^^^^^^^^^^^^^^^^^^^^^^^^^^^^^^^^^
  File "/home/tagordo/snap/code/179/.local/share/virtualenvs/music-quiz-bot-PZw_aL80/lib/python3.12/site-packages/aiohttp/client.py", line 1004, in _ws_connect
    resp = await self.request(
           ^^^^^^^^^^^^^^^^^^^
  File "/home/tagordo/snap/code/179/.local/share/virtualenvs/music-quiz-bot-PZw_aL80/lib/python3.12/site-packages/aiohttp/client.py", line 703, in _request
    conn = await self._connector.connect(
           ^^^^^^^^^^^^^^^^^^^^^^^^^^^^^^
  File "/home/tagordo/snap/code/179/.local/share/virtualenvs/music-quiz-bot-PZw_aL80/lib/python3.12/site-packages/aiohttp/connector.py", line 548, in connect
    proto = await self._create_connection(req, traces, timeout)
            ^^^^^^^^^^^^^^^^^^^^^^^^^^^^^^^^^^^^^^^^^^^^^^^^^^^
  File "/home/tagordo/snap/code/179/.local/share/virtualenvs/music-quiz-bot-PZw_aL80/lib/python3.12/site-packages/aiohttp/connector.py", line 1056, in _create_connection
    _, proto = await self._create_direct_connection(req, traces, timeout)
               ^^^^^^^^^^^^^^^^^^^^^^^^^^^^^^^^^^^^^^^^^^^^^^^^^^^^^^^^^^
  File "/home/tagordo/snap/code/179/.local/share/virtualenvs/music-quiz-bot-PZw_aL80/lib/python3.12/site-packages/aiohttp/connector.py", line 1357, in _create_direct_connection
    raise ClientConnectorDNSError(req.connection_key, exc) from exc
aiohttp.client_exceptions.ClientConnectorDNSError: Cannot connect to host gateway.discord.gg:443 ssl:default [Temporary failure in name resolution]
[2025-02-09 09:57:18] [ERROR   ] discord.client: Attempting a reconnect in 36.95s
Traceback (most recent call last):
  File "/home/tagordo/snap/code/179/.local/share/virtualenvs/music-quiz-bot-PZw_aL80/lib/python3.12/site-packages/aiohttp/connector.py", line 1351, in _create_direct_connection
    hosts = await self._resolve_host(host, port, traces=traces)
            ^^^^^^^^^^^^^^^^^^^^^^^^^^^^^^^^^^^^^^^^^^^^^^^^^^^
  File "/home/tagordo/snap/code/179/.local/share/virtualenvs/music-quiz-bot-PZw_aL80/lib/python3.12/site-packages/aiohttp/connector.py", line 995, in _resolve_host
    return await asyncio.shield(resolved_host_task)
           ^^^^^^^^^^^^^^^^^^^^^^^^^^^^^^^^^^^^^^^^
  File "/home/tagordo/snap/code/179/.local/share/virtualenvs/music-quiz-bot-PZw_aL80/lib/python3.12/site-packages/aiohttp/connector.py", line 1026, in _resolve_host_with_throttle
    addrs = await self._resolver.resolve(host, port, family=self._family)
            ^^^^^^^^^^^^^^^^^^^^^^^^^^^^^^^^^^^^^^^^^^^^^^^^^^^^^^^^^^^^^
  File "/home/tagordo/snap/code/179/.local/share/virtualenvs/music-quiz-bot-PZw_aL80/lib/python3.12/site-packages/aiohttp/resolver.py", line 36, in resolve
    infos = await self._loop.getaddrinfo(
            ^^^^^^^^^^^^^^^^^^^^^^^^^^^^^
  File "/usr/lib/python3.12/asyncio/base_events.py", line 901, in getaddrinfo
    return await self.run_in_executor(
           ^^^^^^^^^^^^^^^^^^^^^^^^^^^
  File "/usr/lib/python3.12/concurrent/futures/thread.py", line 58, in run
    result = self.fn(*self.args, **self.kwargs)
             ^^^^^^^^^^^^^^^^^^^^^^^^^^^^^^^^^^
  File "/usr/lib/python3.12/socket.py", line 963, in getaddrinfo
    for res in _socket.getaddrinfo(host, port, family, type, proto, flags):
               ^^^^^^^^^^^^^^^^^^^^^^^^^^^^^^^^^^^^^^^^^^^^^^^^^^^^^^^^^^^
socket.gaierror: [Errno -3] Temporary failure in name resolution

The above exception was the direct cause of the following exception:

Traceback (most recent call last):
  File "/home/tagordo/snap/code/179/.local/share/virtualenvs/music-quiz-bot-PZw_aL80/lib/python3.12/site-packages/discord/client.py", line 664, in connect
    self.ws = await asyncio.wait_for(coro, timeout=60.0)
              ^^^^^^^^^^^^^^^^^^^^^^^^^^^^^^^^^^^^^^^^^^
  File "/usr/lib/python3.12/asyncio/tasks.py", line 520, in wait_for
    return await fut
           ^^^^^^^^^
  File "/home/tagordo/snap/code/179/.local/share/virtualenvs/music-quiz-bot-PZw_aL80/lib/python3.12/site-packages/discord/gateway.py", line 374, in from_client
    socket = await client.http.ws_connect(str(url))
             ^^^^^^^^^^^^^^^^^^^^^^^^^^^^^^^^^^^^^^
  File "/home/tagordo/snap/code/179/.local/share/virtualenvs/music-quiz-bot-PZw_aL80/lib/python3.12/site-packages/discord/http.py", line 550, in ws_connect
    return await self.__session.ws_connect(url, **kwargs)
           ^^^^^^^^^^^^^^^^^^^^^^^^^^^^^^^^^^^^^^^^^^^^^^
  File "/home/tagordo/snap/code/179/.local/share/virtualenvs/music-quiz-bot-PZw_aL80/lib/python3.12/site-packages/aiohttp/client.py", line 1004, in _ws_connect
    resp = await self.request(
           ^^^^^^^^^^^^^^^^^^^
  File "/home/tagordo/snap/code/179/.local/share/virtualenvs/music-quiz-bot-PZw_aL80/lib/python3.12/site-packages/aiohttp/client.py", line 703, in _request
    conn = await self._connector.connect(
           ^^^^^^^^^^^^^^^^^^^^^^^^^^^^^^
  File "/home/tagordo/snap/code/179/.local/share/virtualenvs/music-quiz-bot-PZw_aL80/lib/python3.12/site-packages/aiohttp/connector.py", line 548, in connect
    proto = await self._create_connection(req, traces, timeout)
            ^^^^^^^^^^^^^^^^^^^^^^^^^^^^^^^^^^^^^^^^^^^^^^^^^^^
  File "/home/tagordo/snap/code/179/.local/share/virtualenvs/music-quiz-bot-PZw_aL80/lib/python3.12/site-packages/aiohttp/connector.py", line 1056, in _create_connection
    _, proto = await self._create_direct_connection(req, traces, timeout)
               ^^^^^^^^^^^^^^^^^^^^^^^^^^^^^^^^^^^^^^^^^^^^^^^^^^^^^^^^^^
  File "/home/tagordo/snap/code/179/.local/share/virtualenvs/music-quiz-bot-PZw_aL80/lib/python3.12/site-packages/aiohttp/connector.py", line 1357, in _create_direct_connection
    raise ClientConnectorDNSError(req.connection_key, exc) from exc
aiohttp.client_exceptions.ClientConnectorDNSError: Cannot connect to host gateway.discord.gg:443 ssl:default [Temporary failure in name resolution]
[2025-02-09 11:39:26] [ERROR   ] discord.client: Attempting a reconnect in 462.75s
Traceback (most recent call last):
  File "/home/tagordo/snap/code/179/.local/share/virtualenvs/music-quiz-bot-PZw_aL80/lib/python3.12/site-packages/aiohttp/connector.py", line 1351, in _create_direct_connection
    hosts = await self._resolve_host(host, port, traces=traces)
            ^^^^^^^^^^^^^^^^^^^^^^^^^^^^^^^^^^^^^^^^^^^^^^^^^^^
  File "/home/tagordo/snap/code/179/.local/share/virtualenvs/music-quiz-bot-PZw_aL80/lib/python3.12/site-packages/aiohttp/connector.py", line 995, in _resolve_host
    return await asyncio.shield(resolved_host_task)
           ^^^^^^^^^^^^^^^^^^^^^^^^^^^^^^^^^^^^^^^^
  File "/home/tagordo/snap/code/179/.local/share/virtualenvs/music-quiz-bot-PZw_aL80/lib/python3.12/site-packages/aiohttp/connector.py", line 1026, in _resolve_host_with_throttle
    addrs = await self._resolver.resolve(host, port, family=self._family)
            ^^^^^^^^^^^^^^^^^^^^^^^^^^^^^^^^^^^^^^^^^^^^^^^^^^^^^^^^^^^^^
  File "/home/tagordo/snap/code/179/.local/share/virtualenvs/music-quiz-bot-PZw_aL80/lib/python3.12/site-packages/aiohttp/resolver.py", line 36, in resolve
    infos = await self._loop.getaddrinfo(
            ^^^^^^^^^^^^^^^^^^^^^^^^^^^^^
  File "/usr/lib/python3.12/asyncio/base_events.py", line 901, in getaddrinfo
    return await self.run_in_executor(
           ^^^^^^^^^^^^^^^^^^^^^^^^^^^
  File "/usr/lib/python3.12/concurrent/futures/thread.py", line 58, in run
    result = self.fn(*self.args, **self.kwargs)
             ^^^^^^^^^^^^^^^^^^^^^^^^^^^^^^^^^^
  File "/usr/lib/python3.12/socket.py", line 963, in getaddrinfo
    for res in _socket.getaddrinfo(host, port, family, type, proto, flags):
               ^^^^^^^^^^^^^^^^^^^^^^^^^^^^^^^^^^^^^^^^^^^^^^^^^^^^^^^^^^^
socket.gaierror: [Errno -3] Temporary failure in name resolution

The above exception was the direct cause of the following exception:

Traceback (most recent call last):
  File "/home/tagordo/snap/code/179/.local/share/virtualenvs/music-quiz-bot-PZw_aL80/lib/python3.12/site-packages/discord/client.py", line 664, in connect
    self.ws = await asyncio.wait_for(coro, timeout=60.0)
              ^^^^^^^^^^^^^^^^^^^^^^^^^^^^^^^^^^^^^^^^^^
  File "/usr/lib/python3.12/asyncio/tasks.py", line 520, in wait_for
    return await fut
           ^^^^^^^^^
  File "/home/tagordo/snap/code/179/.local/share/virtualenvs/music-quiz-bot-PZw_aL80/lib/python3.12/site-packages/discord/gateway.py", line 374, in from_client
    socket = await client.http.ws_connect(str(url))
             ^^^^^^^^^^^^^^^^^^^^^^^^^^^^^^^^^^^^^^
  File "/home/tagordo/snap/code/179/.local/share/virtualenvs/music-quiz-bot-PZw_aL80/lib/python3.12/site-packages/discord/http.py", line 550, in ws_connect
    return await self.__session.ws_connect(url, **kwargs)
           ^^^^^^^^^^^^^^^^^^^^^^^^^^^^^^^^^^^^^^^^^^^^^^
  File "/home/tagordo/snap/code/179/.local/share/virtualenvs/music-quiz-bot-PZw_aL80/lib/python3.12/site-packages/aiohttp/client.py", line 1004, in _ws_connect
    resp = await self.request(
           ^^^^^^^^^^^^^^^^^^^
  File "/home/tagordo/snap/code/179/.local/share/virtualenvs/music-quiz-bot-PZw_aL80/lib/python3.12/site-packages/aiohttp/client.py", line 703, in _request
    conn = await self._connector.connect(
           ^^^^^^^^^^^^^^^^^^^^^^^^^^^^^^
  File "/home/tagordo/snap/code/179/.local/share/virtualenvs/music-quiz-bot-PZw_aL80/lib/python3.12/site-packages/aiohttp/connector.py", line 548, in connect
    proto = await self._create_connection(req, traces, timeout)
            ^^^^^^^^^^^^^^^^^^^^^^^^^^^^^^^^^^^^^^^^^^^^^^^^^^^
  File "/home/tagordo/snap/code/179/.local/share/virtualenvs/music-quiz-bot-PZw_aL80/lib/python3.12/site-packages/aiohttp/connector.py", line 1056, in _create_connection
    _, proto = await self._create_direct_connection(req, traces, timeout)
               ^^^^^^^^^^^^^^^^^^^^^^^^^^^^^^^^^^^^^^^^^^^^^^^^^^^^^^^^^^
  File "/home/tagordo/snap/code/179/.local/share/virtualenvs/music-quiz-bot-PZw_aL80/lib/python3.12/site-packages/aiohttp/connector.py", line 1357, in _create_direct_connection
    raise ClientConnectorDNSError(req.connection_key, exc) from exc
aiohttp.client_exceptions.ClientConnectorDNSError: Cannot connect to host gateway.discord.gg:443 ssl:default [Temporary failure in name resolution]
[2025-02-09 16:04:12] [ERROR   ] discord.client: Attempting a reconnect in 392.19s
Traceback (most recent call last):
  File "/home/tagordo/snap/code/179/.local/share/virtualenvs/music-quiz-bot-PZw_aL80/lib/python3.12/site-packages/aiohttp/connector.py", line 1351, in _create_direct_connection
    hosts = await self._resolve_host(host, port, traces=traces)
            ^^^^^^^^^^^^^^^^^^^^^^^^^^^^^^^^^^^^^^^^^^^^^^^^^^^
  File "/home/tagordo/snap/code/179/.local/share/virtualenvs/music-quiz-bot-PZw_aL80/lib/python3.12/site-packages/aiohttp/connector.py", line 995, in _resolve_host
    return await asyncio.shield(resolved_host_task)
           ^^^^^^^^^^^^^^^^^^^^^^^^^^^^^^^^^^^^^^^^
  File "/home/tagordo/snap/code/179/.local/share/virtualenvs/music-quiz-bot-PZw_aL80/lib/python3.12/site-packages/aiohttp/connector.py", line 1026, in _resolve_host_with_throttle
    addrs = await self._resolver.resolve(host, port, family=self._family)
            ^^^^^^^^^^^^^^^^^^^^^^^^^^^^^^^^^^^^^^^^^^^^^^^^^^^^^^^^^^^^^
  File "/home/tagordo/snap/code/179/.local/share/virtualenvs/music-quiz-bot-PZw_aL80/lib/python3.12/site-packages/aiohttp/resolver.py", line 36, in resolve
    infos = await self._loop.getaddrinfo(
            ^^^^^^^^^^^^^^^^^^^^^^^^^^^^^
  File "/usr/lib/python3.12/asyncio/base_events.py", line 901, in getaddrinfo
    return await self.run_in_executor(
           ^^^^^^^^^^^^^^^^^^^^^^^^^^^
  File "/usr/lib/python3.12/concurrent/futures/thread.py", line 58, in run
    result = self.fn(*self.args, **self.kwargs)
             ^^^^^^^^^^^^^^^^^^^^^^^^^^^^^^^^^^
  File "/usr/lib/python3.12/socket.py", line 963, in getaddrinfo
    for res in _socket.getaddrinfo(host, port, family, type, proto, flags):
               ^^^^^^^^^^^^^^^^^^^^^^^^^^^^^^^^^^^^^^^^^^^^^^^^^^^^^^^^^^^
socket.gaierror: [Errno -3] Temporary failure in name resolution

The above exception was the direct cause of the following exception:

Traceback (most recent call last):
  File "/home/tagordo/snap/code/179/.local/share/virtualenvs/music-quiz-bot-PZw_aL80/lib/python3.12/site-packages/discord/client.py", line 664, in connect
    self.ws = await asyncio.wait_for(coro, timeout=60.0)
              ^^^^^^^^^^^^^^^^^^^^^^^^^^^^^^^^^^^^^^^^^^
  File "/usr/lib/python3.12/asyncio/tasks.py", line 520, in wait_for
    return await fut
           ^^^^^^^^^
  File "/home/tagordo/snap/code/179/.local/share/virtualenvs/music-quiz-bot-PZw_aL80/lib/python3.12/site-packages/discord/gateway.py", line 374, in from_client
    socket = await client.http.ws_connect(str(url))
             ^^^^^^^^^^^^^^^^^^^^^^^^^^^^^^^^^^^^^^
  File "/home/tagordo/snap/code/179/.local/share/virtualenvs/music-quiz-bot-PZw_aL80/lib/python3.12/site-packages/discord/http.py", line 550, in ws_connect
    return await self.__session.ws_connect(url, **kwargs)
           ^^^^^^^^^^^^^^^^^^^^^^^^^^^^^^^^^^^^^^^^^^^^^^
  File "/home/tagordo/snap/code/179/.local/share/virtualenvs/music-quiz-bot-PZw_aL80/lib/python3.12/site-packages/aiohttp/client.py", line 1004, in _ws_connect
    resp = await self.request(
           ^^^^^^^^^^^^^^^^^^^
  File "/home/tagordo/snap/code/179/.local/share/virtualenvs/music-quiz-bot-PZw_aL80/lib/python3.12/site-packages/aiohttp/client.py", line 703, in _request
    conn = await self._connector.connect(
           ^^^^^^^^^^^^^^^^^^^^^^^^^^^^^^
  File "/home/tagordo/snap/code/179/.local/share/virtualenvs/music-quiz-bot-PZw_aL80/lib/python3.12/site-packages/aiohttp/connector.py", line 548, in connect
    proto = await self._create_connection(req, traces, timeout)
            ^^^^^^^^^^^^^^^^^^^^^^^^^^^^^^^^^^^^^^^^^^^^^^^^^^^
  File "/home/tagordo/snap/code/179/.local/share/virtualenvs/music-quiz-bot-PZw_aL80/lib/python3.12/site-packages/aiohttp/connector.py", line 1056, in _create_connection
    _, proto = await self._create_direct_connection(req, traces, timeout)
               ^^^^^^^^^^^^^^^^^^^^^^^^^^^^^^^^^^^^^^^^^^^^^^^^^^^^^^^^^^
  File "/home/tagordo/snap/code/179/.local/share/virtualenvs/music-quiz-bot-PZw_aL80/lib/python3.12/site-packages/aiohttp/connector.py", line 1357, in _create_direct_connection
    raise ClientConnectorDNSError(req.connection_key, exc) from exc
aiohttp.client_exceptions.ClientConnectorDNSError: Cannot connect to host gateway.discord.gg:443 ssl:default [Temporary failure in name resolution]
