[2025-02-01 23:48:54] [INFO    ] discord.client: logging in using static token
[2025-02-01 23:48:55] [INFO    ] discord.gateway: Shard ID None has connected to Gateway (Session ID: 06d91ebfea0c59afa379fec232ae99e2).
[2025-02-01 23:49:13] [INFO    ] discord.voice_state: Connecting to voice...
[2025-02-01 23:49:13] [INFO    ] discord.voice_state: Starting voice handshake... (connection attempt 1)
[2025-02-01 23:49:14] [INFO    ] discord.voice_state: Voice handshake complete. Endpoint found: rotterdam11141.discord.media
[2025-02-01 23:49:14] [INFO    ] discord.voice_state: Voice connection complete.
[2025-02-01 23:49:25] [ERROR   ] discord.client: Ignoring exception in on_message
Traceback (most recent call last):
  File "/home/tagordo/snap/code/179/.local/share/virtualenvs/music-quiz-bot-PZw_aL80/lib/python3.12/site-packages/discord/client.py", line 449, in _run_event
    await coro(*args, **kwargs)
  File "/home/tagordo/Documents/side-projects/music-quiz-bot/bot/cogs/musicQuiz.py", line 122, in on_message
    await MusicQuiz.next_song(ctx)
          ^^^^^^^^^^^^^^^^^^^^^^^^
  File "/home/tagordo/Documents/side-projects/music-quiz-bot/bot/cogs/musicHandler.py", line 86, in next_song
    self.bot.loop.create_task(self.start_song(ctx))
                             ^^^^^^^^^^^^^^^
AttributeError: 'Context' object has no attribute 'start_song'
[2025-02-01 23:49:25] [INFO    ] discord.player: ffmpeg process 68169 has not terminated. Waiting to terminate...
[2025-02-01 23:49:25] [INFO    ] discord.player: ffmpeg process 68169 should have terminated with a return code of -9.
[2025-02-01 23:49:25] [ERROR   ] discord.client: Ignoring exception in on_message
Traceback (most recent call last):
  File "/home/tagordo/snap/code/179/.local/share/virtualenvs/music-quiz-bot-PZw_aL80/lib/python3.12/site-packages/discord/client.py", line 449, in _run_event
    await coro(*args, **kwargs)
  File "/home/tagordo/Documents/side-projects/music-quiz-bot/bot/cogs/musicQuiz.py", line 122, in on_message
    await MusicQuiz.next_song(ctx)
          ^^^^^^^^^^^^^^^^^^^^^^^^
  File "/home/tagordo/Documents/side-projects/music-quiz-bot/bot/cogs/musicHandler.py", line 86, in next_song
    self.bot.loop.create_task(self.start_song(ctx))
                             ^^^^^^^^^^^^^^^
AttributeError: 'Context' object has no attribute 'start_song'
[2025-02-01 23:49:58] [ERROR   ] discord.ext.commands.bot: Ignoring exception in command pass
Traceback (most recent call last):
  File "/home/tagordo/snap/code/179/.local/share/virtualenvs/music-quiz-bot-PZw_aL80/lib/python3.12/site-packages/discord/ext/commands/core.py", line 235, in wrapped
    ret = await coro(*args, **kwargs)
          ^^^^^^^^^^^^^^^^^^^^^^^^^^^
  File "/home/tagordo/Documents/side-projects/music-quiz-bot/bot/cogs/musicQuiz.py", line 152, in pass_song
    await MusicQuiz.next_song(ctx)
          ^^^^^^^^^^^^^^^^^^^^^^^^
  File "/home/tagordo/Documents/side-projects/music-quiz-bot/bot/cogs/musicHandler.py", line 86, in next_song
    self.bot.loop.create_task(self.start_song(ctx))
                             ^^^^^^^^^^^^^^^
AttributeError: 'Context' object has no attribute 'start_song'

The above exception was the direct cause of the following exception:

Traceback (most recent call last):
  File "/home/tagordo/snap/code/179/.local/share/virtualenvs/music-quiz-bot-PZw_aL80/lib/python3.12/site-packages/discord/ext/commands/bot.py", line 1366, in invoke
    await ctx.command.invoke(ctx)
  File "/home/tagordo/snap/code/179/.local/share/virtualenvs/music-quiz-bot-PZw_aL80/lib/python3.12/site-packages/discord/ext/commands/core.py", line 1029, in invoke
    await injected(*ctx.args, **ctx.kwargs)  # type: ignore
    ^^^^^^^^^^^^^^^^^^^^^^^^^^^^^^^^^^^^^^^
  File "/home/tagordo/snap/code/179/.local/share/virtualenvs/music-quiz-bot-PZw_aL80/lib/python3.12/site-packages/discord/ext/commands/core.py", line 244, in wrapped
    raise CommandInvokeError(exc) from exc
discord.ext.commands.errors.CommandInvokeError: Command raised an exception: AttributeError: 'Context' object has no attribute 'start_song'
[2025-02-01 23:49:58] [INFO    ] discord.player: ffmpeg process 68304 has not terminated. Waiting to terminate...
[2025-02-01 23:49:58] [INFO    ] discord.player: ffmpeg process 68304 should have terminated with a return code of -9.
[2025-02-01 23:50:09] [ERROR   ] discord.client: Ignoring exception in on_message
Traceback (most recent call last):
  File "/home/tagordo/snap/code/179/.local/share/virtualenvs/music-quiz-bot-PZw_aL80/lib/python3.12/site-packages/discord/client.py", line 449, in _run_event
    await coro(*args, **kwargs)
  File "/home/tagordo/Documents/side-projects/music-quiz-bot/bot/cogs/musicQuiz.py", line 122, in on_message
    await MusicQuiz.next_song(ctx)
          ^^^^^^^^^^^^^^^^^^^^^^^^
  File "/home/tagordo/Documents/side-projects/music-quiz-bot/bot/cogs/musicHandler.py", line 86, in next_song
    self.bot.loop.create_task(self.start_song(ctx))
                             ^^^^^^^^^^^^^^^
AttributeError: 'Context' object has no attribute 'start_song'
[2025-02-01 23:50:09] [INFO    ] discord.player: ffmpeg process 68715 has not terminated. Waiting to terminate...
[2025-02-01 23:50:09] [INFO    ] discord.player: ffmpeg process 68715 should have terminated with a return code of -9.
[2025-02-01 23:50:09] [ERROR   ] discord.client: Ignoring exception in on_message
Traceback (most recent call last):
  File "/home/tagordo/snap/code/179/.local/share/virtualenvs/music-quiz-bot-PZw_aL80/lib/python3.12/site-packages/discord/client.py", line 449, in _run_event
    await coro(*args, **kwargs)
  File "/home/tagordo/Documents/side-projects/music-quiz-bot/bot/cogs/musicQuiz.py", line 122, in on_message
    await MusicQuiz.next_song(ctx)
          ^^^^^^^^^^^^^^^^^^^^^^^^
  File "/home/tagordo/Documents/side-projects/music-quiz-bot/bot/cogs/musicHandler.py", line 86, in next_song
    self.bot.loop.create_task(self.start_song(ctx))
                             ^^^^^^^^^^^^^^^
AttributeError: 'Context' object has no attribute 'start_song'
[2025-02-01 23:50:42] [INFO    ] discord.player: ffmpeg process 68891 successfully terminated with return code of 0.
[2025-02-01 23:50:42] [ERROR   ] discord.ext.commands.bot: Ignoring exception in command pass
Traceback (most recent call last):
  File "/home/tagordo/snap/code/179/.local/share/virtualenvs/music-quiz-bot-PZw_aL80/lib/python3.12/site-packages/discord/ext/commands/core.py", line 235, in wrapped
    ret = await coro(*args, **kwargs)
          ^^^^^^^^^^^^^^^^^^^^^^^^^^^
  File "/home/tagordo/Documents/side-projects/music-quiz-bot/bot/cogs/musicQuiz.py", line 152, in pass_song
    await MusicQuiz.next_song(ctx)
          ^^^^^^^^^^^^^^^^^^^^^^^^
  File "/home/tagordo/Documents/side-projects/music-quiz-bot/bot/cogs/musicHandler.py", line 86, in next_song
    self.bot.loop.create_task(self.start_song(ctx))
                             ^^^^^^^^^^^^^^^
AttributeError: 'Context' object has no attribute 'start_song'

The above exception was the direct cause of the following exception:

Traceback (most recent call last):
  File "/home/tagordo/snap/code/179/.local/share/virtualenvs/music-quiz-bot-PZw_aL80/lib/python3.12/site-packages/discord/ext/commands/bot.py", line 1366, in invoke
    await ctx.command.invoke(ctx)
  File "/home/tagordo/snap/code/179/.local/share/virtualenvs/music-quiz-bot-PZw_aL80/lib/python3.12/site-packages/discord/ext/commands/core.py", line 1029, in invoke
    await injected(*ctx.args, **ctx.kwargs)  # type: ignore
    ^^^^^^^^^^^^^^^^^^^^^^^^^^^^^^^^^^^^^^^
  File "/home/tagordo/snap/code/179/.local/share/virtualenvs/music-quiz-bot-PZw_aL80/lib/python3.12/site-packages/discord/ext/commands/core.py", line 244, in wrapped
    raise CommandInvokeError(exc) from exc
discord.ext.commands.errors.CommandInvokeError: Command raised an exception: AttributeError: 'Context' object has no attribute 'start_song'
